<robot name="dumpUrdf">
	<material name="blue">
		<specular>0 0 0 0</specular>
	</material>
	
	<link name="base" >
		<inertial>
			<origin rpy = "0 0 0" xyz = "0 0 0" />
			<mass value = "0.00100" />
			<inertia ixx = "0.1" ixy = "0" ixz = "0" iyy = "0.1" iyz = "0" izz = "0.1" />
		</inertial>
	</link>
	<link name="pelvis" >
		<inertial>
			<origin rpy = "0 0 0" xyz = "0.000000 0.280000 0.000000" />
			<mass value = "6.000000" />
			<inertia ixx = "0.1" ixy = "0" ixz = "0" iyy = "0.1" iyz = "0" izz = "0.1" />
		</inertial>
		<collision>
			<origin rpy = "0 0 0" xyz = "0.000000 0.280000 0.000000" />
			<geometry>
				<sphere radius = "0.360000" />
			</geometry>
			<material name="blue" />
		</collision>
	</link>
	<joint name="root" type="fixed" >
		<parent link = "base" />
		<child link="pelvis" />
		<origin rpy = "0 0 0" xyz = "0.000000 0.000000 0.000000" />
	</joint>
	<link name="chest" >
		<inertial>
			<origin rpy = "0 0 0" xyz = "0.000000 0.480000 0.000000" />
			<mass value = "14.000000" />
			<inertia ixx = "0.1" ixy = "0" ixz = "0" iyy = "0.1" iyz = "0" izz = "0.1" />
		</inertial>
		<collision>
				<origin rpy = "0 0 0" xyz = "0.000000 0.480000 0.000000" />
			<geometry>
				<sphere radius = "0.440000" />
			</geometry>
			<material name="blue" />
		</collision>
	</link>
	<joint name="abdomen" type="spherical" >
		<parent link="pelvis" />
		<child link="chest" />
		<origin rpy = "0 0 0" xyz = "0.000000 0.944604 0.000000" />
		<limit effort="200.0" lower="-1.2" upper="1.2" />		
	</joint>
	<link name="head" >
		<inertial>
			<origin rpy = "0 0 0" xyz = "0.000000 0.700000 0.000000" />
			<mass value = "2.000000" />
			<inertia ixx = "0.1" ixy = "0" ixz = "0" iyy = "0.1" iyz = "0" izz = "0.1" />
		</inertial>
		<collision>
			<origin rpy = "0 0 0" xyz = "0.000000 0.700000 0.000000" />
			<geometry>
				<sphere radius = "0.410000" />
			</geometry>
			<material name="blue" />
		</collision>
	</link>
	<joint name="neck" type="spherical" >
		<parent link="chest" />
		<child link="head" />
		<origin rpy = "0 0 0" xyz = "0.000000 0.895576 0.000000" />
		<limit effort="50.0" lower="-1.0" upper="1.0" />	
	</joint>
	<link name="right_thign" >
		<inertial>
				<origin rpy = "0 0 0" xyz = "0.000000 -0.840000 0.000000" />
			 <mass value = "4.500000" />
			<inertia ixx = "0.1" ixy = "0" ixz = "0" iyy = "0.1" iyz = "0" izz = "0.1" />
		</inertial>
		<collision>
			<origin rpy = "-1.570796 0 0" xyz = "0.000000 -0.840000 0.000000" />
			<geometry>
				<capsule length="1.200000" radius="0.220000"/>
			</geometry>
			<material name="blue" />
		</collision>
	</link>
	<joint name="right_hip" type="spherical" >
		<parent link="pelvis" />
		<child link="right_thign" />
		<origin rpy = "0 0 0" xyz = "0.000000 0.000000 0.339548" />
		<limit effort="200.0" lower="-1.57" upper="2.57" />	
	</joint>
	<link name="right_shin" >
		<inertial>
				<origin rpy = "0 0 0" xyz = "0.000000 -0.800000 0.000000" />
			 <mass value = "3.000000" />
			<inertia ixx = "0.1" ixy = "0" ixz = "0" iyy = "0.1" iyz = "0" izz = "0.1" />
		</inertial>
		<collision>
				<origin rpy = "-1.570796 0 0" xyz = "0.000000 -0.800000 0.000000" />
			<geometry>
				<capsule length="1.240000" radius="0.200000"/>
			</geometry>
			<material name="blue" />
		</collision>
	</link>
	<joint name="right_knee" type="revolute" >
		<parent link="right_thign" />
		<child link="right_shin" />
		<origin rpy = "0 0 0" xyz = "0.000000 -1.686184 0.000000" />
		<axis xyz = "0.000000 0.000000 1.000000" />
		<limit effort="150.0" lower="-3.14" upper="0.0" />	
	</joint>
	<link name="right_foot" >
		<inertial>
				<origin rpy = "0 0 0" xyz = "0.180000 -0.090000 0.000000" />
			 <mass value = "1.000000" />
			<inertia ixx = "0.1" ixy = "0" ixz = "0" iyy = "0.1" iyz = "0" izz = "0.1" />
		</inertial>
		<collision>
				<origin rpy = "0 0 0" xyz = "0.180000 -0.090000 0.000000" />
			<geometry>
				<box size="0.708000 0.220000 0.360000" />
			</geometry>
			<material name="blue" />
		</collision>
	</link>
	<joint name="right_ankle" type="spherical" >
		<parent link="right_shin" />
		<child link="right_foot" />
		<origin rpy = "0 0 0" xyz = "0.000000 -1.639480 0.000000" />
		<limit effort="90.0" lower="-1.57" upper="1.57" />	
	</joint>
	<link name="right_upper_arm" >
		<inertial>
				<origin rpy = "0 0 0" xyz = "0.000000 -0.560000 0.000000" />
			 <mass value = "1.500000" />
			<inertia ixx = "0.1" ixy = "0" ixz = "0" iyy = "0.1" iyz = "0" izz = "0.1" />
		</inertial>
		<collision>
			<origin rpy = "-1.570796 0 0" xyz = "0.000000 -0.560000 0.000000" />
			<geometry>
				<capsule length="0.720000" radius="0.180000"/>
			</geometry>
			<material name="blue" />
		</collision>
	</link>
	<joint name="right_shoulder" type="spherical" >
		<parent link="chest" />
		<child link="right_upper_arm" />
		<origin rpy = "0 0 0" xyz = "-0.096200 0.974000 0.732440" />
		<limit effort="100.0" lower="-3.14" upper="3.14" />	
	</joint>
	<link name="right_forearm" >
		<inertial>
				<origin rpy = "0 0 0" xyz = "0.000000 -0.480000 0.000000" />
			 <mass value = "1.000000" />
			<inertia ixx = "0.1" ixy = "0" ixz = "0" iyy = "0.1" iyz = "0" izz = "0.1" />
		</inertial>
		<collision>
				<origin rpy = "-1.570796 0 0" xyz = "0.000000 -0.480000 0.000000" />
			<geometry>
				<capsule length="0.540000" radius="0.160000"/>
			</geometry>
			<material name="blue" />
		</collision>
	</link>
	<joint name="right_elbow" type="revolute" >
		<parent link="right_upper_arm" />
		<child link="right_forearm" />
		<origin rpy = "0 0 0" xyz = "0.000000 -1.099152 0.000000" />
		<axis xyz = "0.000000 0.000000 1.000000" />
		<limit effort="60.0" lower="0.0" upper="3.14" />	
	</joint>
	<link name="right_hand" >
		<inertial>
				<origin rpy = "0 0 0" xyz = "0.000000 0.000000 0.000000" />
			 <mass value = "0.500000" />
			<inertia ixx = "0.1" ixy = "0" ixz = "0" iyy = "0.1" iyz = "0" izz = "0.1" />
		</inertial>
		<collision>
				<origin rpy = "0 0 0" xyz = "0.000000 0.000000 0.000000" />
			<geometry>
				<sphere radius = "0.160000" />
			</geometry>
			<material name="blue" />
		</collision>
	</link>
	<joint name="right_wrist" type="fixed" >
		<parent link="right_forearm" />
		<child link="right_hand" />
		<origin rpy = "0 0 0" xyz = "0.000000 -1.035788 0.000000" />
	</joint>
	<link name="left_thign" >
		<inertial>
				<origin rpy = "0 0 0" xyz = "0.000000 -0.840000 0.000000" />
			 <mass value = "4.500000" />
			<inertia ixx = "0.1" ixy = "0" ixz = "0" iyy = "0.1" iyz = "0" izz = "0.1" />
		</inertial>
		<collision>
				<origin rpy = "-1.570796 0 0" xyz = "0.000000 -0.840000 0.000000" />
			<geometry>
				<capsule length="1.200000" radius="0.220000"/>
			</geometry>
			<material name="blue" />
		</collision>
	</link>
	<joint name="left_hip" type="spherical" >
		<parent link="pelvis" />
		<child link="left_thign" />
		<origin rpy = "0 0 0" xyz = "0.000000 0.000000 -0.339548" />
		<limit effort="200.0" lower="-1.57" upper="2.57" />	
	</joint>
	<link name="left_shin" >
		<inertial>
				<origin rpy = "0 0 0" xyz = "0.000000 -0.800000 0.000000" />
			 <mass value = "3.000000" />
			<inertia ixx = "0.1" ixy = "0" ixz = "0" iyy = "0.1" iyz = "0" izz = "0.1" />
		</inertial>
		<collision>
				<origin rpy = "-1.570796 0 0" xyz = "0.000000 -0.800000 0.000000" />
			<geometry>
				<capsule length="1.240000" radius="0.200000"/>
			</geometry>
			<material name="blue" />
		</collision>
	</link>
	<joint name="left_knee" type="revolute" >
		<parent link="left_thign" />
		<child link="left_shin" />
		<origin rpy = "0 0 0" xyz = "0.000000 -1.686184 0.000000" />
		<axis xyz = "0.000000 0.000000 1.000000" />
		<limit effort="150.0" lower="-3.14" upper="0.0" />	
	</joint>
	<link name="left_foot" >
		<inertial>
				<origin rpy = "0 0 0" xyz = "0.180000 -0.090000 0.000000" />
			 <mass value = "1.000000" />
			<inertia ixx = "0.1" ixy = "0" ixz = "0" iyy = "0.1" iyz = "0" izz = "0.1" />
		</inertial>
		<collision>
				<origin rpy = "0 0 0" xyz = "0.180000 -0.090000 0.000000" />
			<geometry>
				<box size="0.708000 0.220000 0.360000" />
			</geometry>
			<material name="blue" />
		</collision>
	</link>
	<joint name="left_ankle" type="spherical" >
		<parent link="left_shin" />
		<child link="left_foot" />
		<origin rpy = "0 0 0" xyz = "0.000000 -1.639480 0.000000" />
		<limit effort="90.0" lower="-1.57" upper="1.57" />	
	</joint>
	<link name="left_upper_arm" >
		<inertial>
				<origin rpy = "0 0 0" xyz = "0.000000 -0.560000 0.000000" />
			 <mass value = "1.500000" />
			<inertia ixx = "0.1" ixy = "0" ixz = "0" iyy = "0.1" iyz = "0" izz = "0.1" />
		</inertial>
		<collision>
				<origin rpy = "-1.570796 0 0" xyz = "0.000000 -0.560000 0.000000" />
			<geometry>
				<capsule length="0.720000" radius="0.180000"/>
			</geometry>
			<material name="blue" />
		</collision>
	</link>
	<joint name="left_shoulder" type="spherical" >
		<parent link="chest" />
		<child link="left_upper_arm" />
		<origin rpy = "0 0 0" xyz = "-0.096200 0.974000 -0.732440" />
		<limit effort="100.0" lower="-1.5" upper="3.14" />	
	</joint>
	<link name="left_forearm" >
		<inertial>
				<origin rpy = "0 0 0" xyz = "0.000000 -0.480000 0.000000" />
			 <mass value = "1.000000" />
			<inertia ixx = "0.1" ixy = "0" ixz = "0" iyy = "0.1" iyz = "0" izz = "0.1" />
		</inertial>
		<collision>
				<origin rpy = "-1.570796 0 0" xyz = "0.000000 -0.480000 0.000000" />
			<geometry>
				<capsule length="0.540000" radius="0.160000"/>
			</geometry>
			<material name="blue" />
		</collision>
	</link>
	<joint name="left_elbow" type="revolute" >
		<parent link="left_upper_arm" />
		<child link="left_forearm" />
		<origin rpy = "0 0 0" xyz = "0.000000 -1.099152 0.000000" />
		<axis xyz = "0.000000 0.000000 1.000000" />
		<limit effort="60.0" lower="0.0" upper="3.14" />	
	</joint>
	<link name="left_hand" >
		<inertial>
				<origin rpy = "0 0 0" xyz = "0.000000 0.000000 0.000000" />
			 <mass value = "0.500000" />
			<inertia ixx = "0.1" ixy = "0" ixz = "0" iyy = "0.1" iyz = "0" izz = "0.1" />
		</inertial>
		<collision>
				<origin rpy = "0 0 0" xyz = "0.000000 0.000000 0.000000" />
			<geometry>
				<sphere radius = "0.160000" />
			</geometry>
			<material name="blue" />
		</collision>
	</link>
	<joint name="left_wrist" type="fixed" >
		<parent link="left_forearm" />
		<child link="left_hand" />
				<origin rpy = "0 0 0" xyz = "0.000000 -1.035788 0.000000" />
	</joint>
</robot>
